<?xml version="1.0" ?>
<!-- =================================================================================== -->
<!-- |    This document was autogenerated by xacro from holobot.xacro                  | -->
<!-- |    EDITING THIS FILE BY HAND IS NOT RECOMMENDED                                 | -->
<!-- =================================================================================== -->
<robot name="holobot" xmlns:xacro="http://www.ros.org/wiki/xacro">
  <!--chassis-->
  <!--TODO calculate inertia and mass-->
  <link name="base_link">
    <inertial>
      <mass value="1.0"/>
      <origin rpy="0 0 0" xyz="0 0 0.02667"/>
      <inertia ixx="0.0" ixy="0.0" ixz="0.0" iyy="0.0" iyz="0.0" izz="0.0"/>
    </inertial>
    <visual name="base_visual">
      <origin rpy="0 0 0" xyz="0 0 0.02667"/>
      <geometry name="holobot_geom">
        <box size="0.3556 0.2286 0.04826"/>
      </geometry>
    </visual>
    <collision>
      <origin rpy="0 0 0" xyz="0 0 5"/>
      <geometry>
        <box size="0.3556 0.2286 0.04826"/>
      </geometry>
    </collision>
  </link>
  <gazebo reference="base_link">
    <material>Gazebo/Black</material>
  </gazebo>
  <!--Front axles+wheels-->
  <!--TODO calculate friction of wheels, color the black rubbers-->
  <link name="holo_front_left_axle">
    <inertial>
      <mass value="0.1"/>
      <origin xyz="0 0 0"/>
      <inertia ixx="1" ixy="0" ixz="0" iyy="1" iyz="0" izz="1"/>
    </inertial>
    <visual name="base_visual">
      <origin rpy="-1.57079635 0 0" xyz="0 0 0"/>
      <geometry name="holo_geom">
        <cylinder length="0.0535" radius="0.0085"/>
      </geometry>
    </visual>
    <collision>
      <origin rpy="-1.57079635 0 0" xyz="0 0 0"/>
      <geometry>
        <box size="0 0 0"/>
      </geometry>
    </collision>
  </link>
  <gazebo reference="holo_front_left_axle">
    <material value="Gazebo/Grey"/>
  </gazebo>
  <joint name="base_front_left_axle_joint" type="fixed">
    <origin rpy="0 0 0" xyz="0.1397 0.1401 0.02413"/>
    <parent link="base_link"/>
    <child link="holo_front_left_axle"/>
  </joint>
  <link name="holo_front_left_wheel">
    <inertial>
      <mass value="0.5"/>
      <origin xyz="0 0 0"/>
      <inertia ixx="0.012" ixy="0" ixz="0" iyy="0.015" iyz="0" izz="0.01176"/>
    </inertial>
    <visual name="base_visual">
      <origin rpy="0 0 0" xyz="0 0 0"/>
      <geometry name="holo_geom">
        <mesh filename="package://simulate_holobot/meshes/wheel.stl" scale="0.001 0.001 0.001"/>
      </geometry>
    </visual>
    <collision>
      <origin rpy="-0.02667 0 0" xyz="0 0 0"/>
      <geometry>
        <mesh filename="package://simulate_holobot/meshes/wheel.stl" scale="0.001 0.001 0.001"/>
        <!--cylinder radius="0.111" lengt="0.075"/-->
      </geometry>
    </collision>
  </link>
  <gazebo reference="holo_front_left_wheel">
    <material value="Gazebo/Green"/>
  </gazebo>
  <joint name="holo_front_left_wheel_joint" type="continuous">
    <axis xyz="0 1 0"/>
    <anchor xyz="0 0 0"/>
    <origin rpy="0 0 0" xyz="0 -0.0210 0"/>
    <parent link="holo_front_left_axle"/>
    <child link="holo_front_left_wheel"/>
    <limit effort="100" velocity="100"/>
    <joint_properties damping="0.7"/>
  </joint>
  <gazebo reference="holo_front_left_wheel">
    <kp>1000000.0</kp>
    <!-- kp and kd for rubber -->
    <kd>100.0</kd>
    <mu1>10.0</mu1>
    <mu2>1.0</mu2>
    <fdir1>0 1 0</fdir1>
    <!-- is this correct? -->
    <maxVel>1.0</maxVel>
    <minDepth>0.00</minDepth>
  </gazebo>
  <link name="holo_front_right_axle">
    <inertial>
      <mass value="0.1"/>
      <origin xyz="0 0 0"/>
      <inertia ixx="1" ixy="0" ixz="0" iyy="1" iyz="0" izz="1"/>
    </inertial>
    <visual name="base_visual">
      <origin rpy="-1.57079635 3.1415927 0" xyz="0 0 0"/>
      <geometry name="holo_geom">
        <cylinder length="0.0535" radius="0.0085"/>
      </geometry>
    </visual>
    <collision>
      <origin rpy="-1.57079635 0 0" xyz="0 0 0"/>
      <geometry>
        <box size="0 0 0"/>
      </geometry>
    </collision>
  </link>
  <gazebo reference="holo_front_right_axle">
    <material value="Gazebo/Grey"/>
  </gazebo>
  <!--TODO calculate exact y joint value-->
  <joint name="base_front_right_axle_joint" type="fixed">
    <origin rpy="0 0 0" xyz="0.1397 -0.1401 0.02413"/>
    <parent link="base_link"/>
    <child link="holo_front_right_axle"/>
  </joint>
  <link name="holo_front_right_wheel">
    <inertial>
      <mass value="0.5"/>
      <origin xyz="0 0 0"/>
      <inertia ixx="0.012" ixy="0" ixz="0" iyy="0.015" iyz="0" izz="0.01176"/>
    </inertial>
    <visual name="base_visual">
      <origin rpy="0 0 0" xyz="0 0 0"/>
      <geometry name="holo_geom">
        <mesh filename="package://simulate_holobot/meshes/wheel.stl" scale="0.001 0.001 0.001"/>
      </geometry>
    </visual>
    <collision>
      <origin rpy="-0.02667 0 0" xyz="0 0 0"/>
      <geometry>
        <mesh filename="package://simulate_holobot/meshes/wheel.stl" scale="0.001 0.001 0.001"/>
        <!--cylinder radius="0.111" lengt="0.075"/-->
      </geometry>
    </collision>
  </link>
  <gazebo reference="holo_front_right_wheel">
    <material value="Gazebo/Green"/>
  </gazebo>
  <joint name="holo_front_right_wheel_joint" type="continuous">
    <axis xyz="0 1 0"/>
    <anchor xyz="0 0 0"/>
    <origin rpy="0 0 0" xyz="0 -0.02500 0"/>
    <parent link="holo_front_right_axle"/>
    <child link="holo_front_right_wheel"/>
    <limit effort="100" velocity="100"/>
    <joint_properties damping="0.7"/>
  </joint>
  <gazebo reference="holo_front_right_wheel">
    <kp>1000000.0</kp>
    <!-- kp and kd for rubber -->
    <kd>100.0</kd>
    <mu1>10.0</mu1>
    <mu2>1.0</mu2>
    <fdir1>0 1 0</fdir1>
    <!-- is this correct? -->
    <maxVel>1.0</maxVel>
    <minDepth>0.00</minDepth>
  </gazebo>
  <!---Back axle+wheel-->
  <!--TODO check friction value,position of wheels-->
  <link name="holo_back_left_axle">
    <inertial>
      <mass value="0.1"/>
      <origin xyz="0 0 0"/>
      <inertia ixx="1" ixy="0" ixz="0" iyy="1" iyz="0" izz="1"/>
    </inertial>
    <visual name="base_visual">
      <origin rpy="-1.57079635 0 0" xyz="0 0 0"/>
      <geometry name="holo_geom">
        <cylinder length="0.0535" radius="0.0085"/>
      </geometry>
    </visual>
    <collision>
      <origin rpy="-1.57079635 0 0" xyz="0 0 0"/>
      <geometry>
        <box size="0 0 0"/>
      </geometry>
    </collision>
  </link>
  <gazebo reference="holo_back_left_axle">
    <material value="Gazebo/Grey"/>
  </gazebo>
  <joint name="base_back_left_axle_joint" type="fixed">
    <origin rpy="0 0 0" xyz="-0.1397 0.1401 0.02413"/>
    <parent link="base_link"/>
    <child link="holo_back_left_axle"/>
  </joint>
  <link name="holo_back_left_wheel">
    <inertial>
      <mass value="0.5"/>
      <origin xyz="0 0 0"/>
      <inertia ixx="0.012" ixy="0" ixz="0" iyy="0.015" iyz="0" izz="0.01176"/>
    </inertial>
    <visual name="base_visual">
      <origin rpy="0 0 0" xyz="0 0 0"/>
      <geometry name="holo_geom">
        <mesh filename="package://simulate_holobot/meshes/wheel.stl" scale="0.001 0.001 0.001"/>
      </geometry>
    </visual>
    <collision>
      <origin rpy="-0.02667 0 0" xyz="0 0 0"/>
      <geometry>
        <mesh filename="package://simulate_holobot/meshes/wheel.stl" scale="0.001 0.001 0.001"/>
        <!--cylinder radius="0.111" lengt="0.075"/-->
      </geometry>
    </collision>
  </link>
  <gazebo reference="holo_back_left_wheel">
    <material value="Gazebo/Green"/>
  </gazebo>
  <joint name="holo_back_left_wheel_joint" type="continuous">
    <axis xyz="0 1 0"/>
    <anchor xyz="0 0 0"/>
    <origin rpy="0 0 0" xyz="0 -0.021 0"/>
    <parent link="holo_back_left_axle"/>
    <child link="holo_back_left_wheel"/>
    <limit effort="100" velocity="100"/>
    <joint_properties damping="0.7"/>
  </joint>
  <gazebo reference="holo_back_left_wheel">
    <kp>1000000.0</kp>
    <!-- kp and kd for rubber -->
    <kd>100.0</kd>
    <mu1>10.0</mu1>
    <mu2>1.0</mu2>
    <fdir1>0 1 0</fdir1>
    <!-- is this correct? -->
    <maxVel>1.0</maxVel>
    <minDepth>0.00</minDepth>
  </gazebo>
  <link name="holo_back_right_axle">
    <inertial>
      <mass value="0.1"/>
      <origin xyz="0 0 0"/>
      <inertia ixx="1" ixy="0" ixz="0" iyy="1" iyz="0" izz="1"/>
    </inertial>
    <visual name="base_visual">
      <origin rpy="-1.57079635 3.1415927 0" xyz="0 0 0"/>
      <geometry name="holo_geom">
        <cylinder length="0.0535" radius="0.0085"/>
      </geometry>
    </visual>
    <collision>
      <origin rpy="-1.57079635 0 0" xyz="0 0 0"/>
      <geometry>
        <box size="0 0 0"/>
      </geometry>
    </collision>
  </link>
  <gazebo reference="holo_back_right_axle">
    <material value="Gazebo/Grey"/>
  </gazebo>
  <!--TODO calculate exact y joint value-->
  <joint name="base_back_right_axle_joint" type="fixed">
    <origin rpy="0 0 0" xyz="-0.1397 -0.1401 0.02413"/>
    <parent link="base_link"/>
    <child link="holo_back_right_axle"/>
  </joint>
  <link name="holo_back_right_wheel">
    <inertial>
      <mass value="0.5"/>
      <origin xyz="0 0 0"/>
      <inertia ixx="0.012" ixy="0" ixz="0" iyy="0.015" iyz="0" izz="0.01176"/>
    </inertial>
    <visual name="base_visual">
      <origin rpy="0 0 0" xyz="0 0 0"/>
      <geometry name="holo_geom">
        <mesh filename="package://simulate_holobot/meshes/wheel.stl" scale="0.001 0.001 0.001"/>
      </geometry>
    </visual>
    <collision>
      <origin rpy="-0.02667 0 0" xyz="0 0 0"/>
      <geometry>
        <mesh filename="package://simulate_holobot/meshes/wheel.stl" scale="0.001 0.001 0.001"/>
        <!--cylinder radius="0.111" lengt="0.075"/-->
      </geometry>
    </collision>
  </link>
  <gazebo reference="holo_back_right_wheel">
    <material value="Gazebo/Green"/>
  </gazebo>
  <joint name="holo_back_right_wheel_joint" type="continuous">
    <axis xyz="0 1 0"/>
    <anchor xyz="0 0 0"/>
    <origin rpy="0 0 0" xyz="0 -0.02500 0"/>
    <parent link="holo_back_right_axle"/>
    <child link="holo_back_right_wheel"/>
    <limit effort="100" velocity="100"/>
    <joint_properties damping="0.7"/>
  </joint>
  <gazebo reference="holo_back_right_wheel">
    <kp>1000000.0</kp>
    <!-- kp and kd for rubber -->
    <kd>100.0</kd>
    <mu1>10.0</mu1>
    <mu2>1.0</mu2>
    <fdir1>0 1 0</fdir1>
    <!-- is this correct? -->
    <maxVel>1.0</maxVel>
    <minDepth>0.00</minDepth>
  </gazebo>
</robot>

